2016-10-08 12:48:39,210 DEBUG A log message
2016-10-08 12:50:00,198 WARNING Not Found: /
2016-10-08 12:50:11,095 ERROR Internal Server Error: /order/create/
Traceback (most recent call last):
  File "/usr/local/lib/python3.4/dist-packages/django/core/handlers/base.py", line 149, in get_response
    response = self.process_exception_by_middleware(e, request)
  File "/usr/local/lib/python3.4/dist-packages/django/core/handlers/base.py", line 147, in get_response
    response = wrapped_callback(request, *callback_args, **callback_kwargs)
  File "/usr/local/lib/python3.4/dist-packages/django/contrib/auth/decorators.py", line 23, in _wrapped_view
    return view_func(request, *args, **kwargs)
  File "/root/syan/booksite/order/views.py", line 36, in order_create
    related_books = related_books[:5]
UnboundLocalError: local variable 'related_books' referenced before assignment
2016-10-08 12:54:36,023 WARNING Not Found: /
2016-10-08 12:56:19,882 WARNING Not Found: /favicon.ico
2016-10-08 12:56:41,359 ERROR Internal Server Error: /accounts/profile/
Traceback (most recent call last):
  File "/usr/local/lib/python3.4/dist-packages/django/core/handlers/base.py", line 149, in get_response
    response = self.process_exception_by_middleware(e, request)
  File "/usr/local/lib/python3.4/dist-packages/django/core/handlers/base.py", line 147, in get_response
    response = wrapped_callback(request, *callback_args, **callback_kwargs)
  File "/root/syan/booksite/accounts/views.py", line 79, in profile_detail
    profile= UserProfile.objects.get(user= request.user)
  File "/usr/local/lib/python3.4/dist-packages/django/db/models/manager.py", line 122, in manager_method
    return getattr(self.get_queryset(), name)(*args, **kwargs)
  File "/usr/local/lib/python3.4/dist-packages/django/db/models/query.py", line 378, in get
    clone = self.filter(*args, **kwargs)
  File "/usr/local/lib/python3.4/dist-packages/django/db/models/query.py", line 790, in filter
    return self._filter_or_exclude(False, *args, **kwargs)
  File "/usr/local/lib/python3.4/dist-packages/django/db/models/query.py", line 808, in _filter_or_exclude
    clone.query.add_q(Q(*args, **kwargs))
  File "/usr/local/lib/python3.4/dist-packages/django/db/models/sql/query.py", line 1243, in add_q
    clause, _ = self._add_q(q_object, self.used_aliases)
  File "/usr/local/lib/python3.4/dist-packages/django/db/models/sql/query.py", line 1269, in _add_q
    allow_joins=allow_joins, split_subq=split_subq,
  File "/usr/local/lib/python3.4/dist-packages/django/db/models/sql/query.py", line 1174, in build_filter
    self.check_related_objects(field, value, opts)
  File "/usr/local/lib/python3.4/dist-packages/django/db/models/sql/query.py", line 1073, in check_related_objects
    for v in value:
  File "/usr/local/lib/python3.4/dist-packages/django/utils/functional.py", line 205, in inner
    return func(self._wrapped, *args)
TypeError: 'AnonymousUser' object is not iterable
2016-10-08 12:56:48,578 WARNING Not Found: /favicon.ico
2016-10-08 12:57:20,402 WARNING Not Found: /
2016-10-08 12:58:35,232 ERROR Internal Server Error: /accounts/profile/
Traceback (most recent call last):
  File "/usr/local/lib/python3.4/dist-packages/django/core/handlers/base.py", line 149, in get_response
    response = self.process_exception_by_middleware(e, request)
  File "/usr/local/lib/python3.4/dist-packages/django/core/handlers/base.py", line 147, in get_response
    response = wrapped_callback(request, *callback_args, **callback_kwargs)
  File "/root/syan/booksite/accounts/views.py", line 79, in profile_detail
    profile= UserProfile.objects.get(user= request.user)
  File "/usr/local/lib/python3.4/dist-packages/django/db/models/manager.py", line 122, in manager_method
    return getattr(self.get_queryset(), name)(*args, **kwargs)
  File "/usr/local/lib/python3.4/dist-packages/django/db/models/query.py", line 378, in get
    clone = self.filter(*args, **kwargs)
  File "/usr/local/lib/python3.4/dist-packages/django/db/models/query.py", line 790, in filter
    return self._filter_or_exclude(False, *args, **kwargs)
  File "/usr/local/lib/python3.4/dist-packages/django/db/models/query.py", line 808, in _filter_or_exclude
    clone.query.add_q(Q(*args, **kwargs))
  File "/usr/local/lib/python3.4/dist-packages/django/db/models/sql/query.py", line 1243, in add_q
    clause, _ = self._add_q(q_object, self.used_aliases)
  File "/usr/local/lib/python3.4/dist-packages/django/db/models/sql/query.py", line 1269, in _add_q
    allow_joins=allow_joins, split_subq=split_subq,
  File "/usr/local/lib/python3.4/dist-packages/django/db/models/sql/query.py", line 1174, in build_filter
    self.check_related_objects(field, value, opts)
  File "/usr/local/lib/python3.4/dist-packages/django/db/models/sql/query.py", line 1073, in check_related_objects
    for v in value:
  File "/usr/local/lib/python3.4/dist-packages/django/utils/functional.py", line 205, in inner
    return func(self._wrapped, *args)
TypeError: 'AnonymousUser' object is not iterable
2016-10-09 00:03:41,561 WARNING Not Found: /http:/www.baidu.com/cache/global/img/gs.gif
2016-10-09 02:01:23,259 WARNING Not Found: /http:/wap.ip138.com/
2016-10-09 07:45:42,173 WARNING Not Found: /cgi-bin/system_cmd.cgi
2016-10-09 07:48:24,324 WARNING Not Found: /cgi-bin/gui_shell.cgi
2016-10-09 09:06:44,430 WARNING Not Found: /http:/www.baidu.com/cache/global/img/gs.gif
2016-10-09 11:32:06,098 WARNING Not Found: /http:/www.baidu.com/cache/global/img/gs.gif
2016-10-09 13:32:34,183 WARNING Not Found: /favicon.ico
2016-10-09 22:44:29,829 WARNING Not Found: /http:/www.baidu.com/cache/global/img/gs.gif
2016-10-10 16:48:09,143 WARNING Not Found: /http:/www.baidu.com/cache/global/img/gs.gif
2016-10-10 21:29:20,495 WARNING Not Found: /http:/www.baidu.com/cache/global/img/gs.gif
2016-10-11 01:27:06,042 WARNING Not Found: /http:/www.baidu.com/cache/global/img/gs.gif
